Workbook

Sheet Calendario
A1: =UPPER("Calendario de tareas QF · Droguería · "&C2&" "&F2) -> CALENDARIO DE TAREAS QF · DROGUERÍA · NOVIEMBRE 2026
B2: Mes: | C2: Noviembre | E2: Año: | F2: 2026 | H2: Plan 4ª semana (mes de 5 sem.): | K2: 3 | M2: =Configuración!B9&" semanas" -> 4 semanas
A3: Leyenda | C3: REC · Recepción, pedidos y distribución | E3: TEM · Temperatura y humedad (T° y HR) | G3: INV · Inventario y vencimientos | I3: CTR · Estupefacientes y psicotrópicos | K3: CAL · Calidad / BPAD / procedimientos
C4: REG · Farmacovigilancia y autoridad sanitaria | E4: ADM · Administrativo y finanzas | G4: EQP · Equipo, coordinación y capacitación | I4: Fecha de mes contiguo | K4: Feriado
A6: ="SEMANA 1" -> SEMANA 1 | B6: =IF(Configuración!$C$12=0,"No aplica este mes","Plan Semana "&Configuración!$D$12&" · "&INDEX('Plan semanal'!$B$1:$B$40,4+(Configuración!$D$12-1)*6)) -> Plan Semana 1 · RECEPCIÓN CENABAST / CRÍTICOS Y PE LISTOS | M6: Avance
B7: Fecha | C7: =Configuración!$B$12+0 -> 46328 | D7: =C7 -> 46328 | E7: =Configuración!$B$12+1 -> 46329 | F7: =E7 -> 46329 | G7: =Configuración!$B$12+2 -> 46330 | H7: =G7 -> 46330 | I7: =Configuración!$B$12+3 -> 46331 | J7: =I7 -> 46331 | K7: =Configuración!$B$12+4 -> 46332 | L7: =K7 -> 46332 | M7: =IFERROR(((COUNTIF(Configuración!$M$4:$M$80,C$7)=0)*(D9="✓")+(COUNTIF(Configuración!$M$4:$M$80,C$7)=0)*(D10="✓")+(COUNTIF(Configuración!$M$4:$M$80,E$7)=0)*(F9="✓")+(COUNTIF(Configuración!$M$4:$M$80,E$7)=0)*(F10="✓")+(COUNTIF(Configuración!$M$4:$M$80,G$7)=0)*(H9="✓")+(COUNTIF(Configuración!$M$4:$M$80,G$7)=0)*(H10="✓")+(COUNTIF(Configuración!$M$4:$M$80,I$7)=0)*(J9="✓")+(COUNTIF(Configuración!$M$4:$M$80,I$7)=0)*(J10="✓")+(COUNTIF(Configuración!$M$4:$M$80,K$7)=0)*(L9="✓")+(COUNTIF(Configuración!$M$4:$M$80,K$7)=0)*(L10="✓"))/((COUNTIF(Configuración!$M$4:$M$80,C$7)=0)*(C9<>"")*(D9<>"N/A")+(COUNTIF(Configuración!$M$4:$M$80,C$7)=0)*(C10<>"")*(D10<>"N/A")+(COUNTIF(Configuración!$M$4:$M$80,E$7)=0)*(E9<>"")*(F9<>"N/A")+(COUNTIF(Configuración!$M$4:$M$80,E$7)=0)*(E10<>"")*(F10<>"N/A")+(COUNTIF(Configuración!$M$4:$M$80,G$7)=0)*(G9<>"")*(H9<>"N/A")+(COUNTIF(Configuración!$M$4:$M$80,G$7)=0)*(G10<>"")*(H10<>"N/A")+(COUNTIF(Configuración!$M$4:$M$80,I$7)=0)*(I9<>"")*(J9<>"N/A")+(COUNTIF(Configuración!$M$4:$M$80,I$7)=0)*(I10<>"")*(J10<>"N/A")+(COUNTIF(Configuración!$M$4:$M$80,K$7)=0)*(K9<>"")*(L9<>"N/A")+(COUNTIF(Configuración!$M$4:$M$80,K$7)=0)*(K10<>"")*(L10<>"N/A")),"") -> 0
B8: Todos los días | C8: =IF(Configuración!$C$12=0,"",INDEX('Plan semanal'!$C$1:$C$40,4+(Configuración!$D$12-1)*6+2)&"") -> T° y HR AM/PM en bodegas · Recepción técnica y liberación de cuarentena · Revisión de alertas ISP / retiros del mercado
B9: AM | C9: =IF(Configuración!$C$12=0,"",INDEX('Plan semanal'!$C$1:$G$40,4+(Configuración!$D$12-1)*6+3,1)&"") -> TEM · Bajar info Data Logger / Revisión QFs: T° y H% aplicar CAPAs | E9: =IF(Configuración!$C$12=0,"",INDEX('Plan semanal'!$C$1:$G$40,4+(Configuración!$D$12-1)*6+3,2)&"") -> INV · Segregar vencidos + correo sobrestock (HPM-SSDR-SAR-SAPU) | G9: =IF(Configuración!$C$12=0,"",INDEX('Plan semanal'!$C$1:$G$40,4+(Configuración!$D$12-1)*6+3,3)&"") -> REC · Críticos + PE | I9: =IF(Configuración!$C$12=0,"",INDEX('Plan semanal'!$C$1:$G$40,4+(Configuración!$D$12-1)*6+3,4)&"") -> EQP · QF Programas / QF Droguería | K9: =IF(Configuración!$C$12=0,"",INDEX('Plan semanal'!$C$1:$G$40,4+(Configuración!$D$12-1)*6+3,5)&"") -> ADM · Guía N399
B10: PM | C10: =IF(Configuración!$C$12=0,"",INDEX('Plan semanal'!$C$1:$G$40,4+(Configuración!$D$12-1)*6+4,1)&"") -> CTR · Cuadratura física de estupefacientes y psicotrópicos (cierre mes anterior) | E10: =IF(Configuración!$C$12=0,"",INDEX('Plan semanal'!$C$1:$G$40,4+(Configuración!$D$12-1)*6+4,2)&"") -> REC · No conformidades de recepción (faltantes, daños, T° fuera de rango) → reclamo a CENABAST/proveedor | G10: =IF(Configuración!$C$12=0,"",INDEX('Plan semanal'!$C$1:$G$40,4+(Configuración!$D$12-1)*6+4,3)&"") -> ADM · Facturas firmadas listas para Finanzas | I10: =IF(Configuración!$C$12=0,"",INDEX('Plan semanal'!$C$1:$G$40,4+(Configuración!$D$12-1)*6+4,4)&"") -> EQP · Programación 2 QF | K10: =IF(Configuración!$C$12=0,"",INDEX('Plan semanal'!$C$1:$G$40,4+(Configuración!$D$12-1)*6+4,5)&"") -> CAL · Actualizar procedimientos
A12: ="SEMANA 2" -> SEMANA 2 | B12: =IF(Configuración!$C$13=0,"No aplica este mes","Plan Semana "&Configuración!$D$13&" · "&INDEX('Plan semanal'!$B$1:$B$40,4+(Configuración!$D$13-1)*6)) -> Plan Semana 2 · GESTIÓN SANITARIA: CONTROLADOS, VENCIMIENTOS Y FARMACOVIGILANCIA | M12: Avance
B13: Fecha | C13: =Configuración!$B$13+0 -> 46335 | D13: =C13 -> 46335 | E13: =Configuración!$B$13+1 -> 46336 | F13: =E13 -> 46336 | G13: =Configuración!$B$13+2 -> 46337 | H13: =G13 -> 46337 | I13: =Configuración!$B$13+3 -> 46338 | J13: =I13 -> 46338 | K13: =Configuración!$B$13+4 -> 46339 | L13: =K13 -> 46339 | M13: =IFERROR(((COUNTIF(Configuración!$M$4:$M$80,C$13)=0)*(D15="✓")+(COUNTIF(Configuración!$M$4:$M$80,C$13)=0)*(D16="✓")+(COUNTIF(Configuración!$M$4:$M$80,E$13)=0)*(F15="✓")+(COUNTIF(Configuración!$M$4:$M$80,E$13)=0)*(F16="✓")+(COUNTIF(Configuración!$M$4:$M$80,G$13)=0)*(H15="✓")+(COUNTIF(Configuración!$M$4:$M$80,G$13)=0)*(H16="✓")+(COUNTIF(Configuración!$M$4:$M$80,I$13)=0)*(J15="✓")+(COUNTIF(Configuración!$M$4:$M$80,I$13)=0)*(J16="✓")+(COUNTIF(Configuración!$M$4:$M$80,K$13)=0)*(L15="✓")+(COUNTIF(Configuración!$M$4:$M$80,K$13)=0)*(L16="✓"))/((COUNTIF(Configuración!$M$4:$M$80,C$13)=0)*(C15<>"")*(D15<>"N/A")+(COUNTIF(Configuración!$M$4:$M$80,C$13)=0)*(C16<>"")*(D16<>"N/A")+(COUNTIF(Configuración!$M$4:$M$80,E$13)=0)*(E15<>"")*(F15<>"N/A")+(COUNTIF(Configuración!$M$4:$M$80,E$13)=0)*(E16<>"")*(F16<>"N/A")+(COUNTIF(Configuración!$M$4:$M$80,G$13)=0)*(G15<>"")*(H15<>"N/A")+(COUNTIF(Configuración!$M$4:$M$80,G$13)=0)*(G16<>"")*(H16<>"N/A")+(COUNTIF(Configuración!$M$4:$M$80,I$13)=0)*(I15<>"")*(J15<>"N/A")+(COUNTIF(Configuración!$M$4:$M$80,I$13)=0)*(I16<>"")*(J16<>"N/A")+(COUNTIF(Configuración!$M$4:$M$80,K$13)=0)*(K15<>"")*(L15<>"N/A")+(COUNTIF(Configuración!$M$4:$M$80,K$13)=0)*(K16<>"")*(L16<>"N/A")),"") -> 0
B14: Todos los días | C14: =IF(Configuración!$C$13=0,"",INDEX('Plan semanal'!$C$1:$C$40,4+(Configuración!$D$13-1)*6+2)&"") -> T° y HR AM/PM en bodegas · Revisión y firma de despachos · Revisión de alertas ISP / retiros del mercado · Custodia de bodega de controlados
B15: AM | C15: =IF(Configuración!$C$13=0,"",INDEX('Plan semanal'!$C$1:$G$40,4+(Configuración!$D$13-1)*6+3,1)&"") -> CTR · Revisión de libro de controlados | E15: =IF(Configuración!$C$13=0,"",INDEX('Plan semanal'!$C$1:$G$40,4+(Configuración!$D$13-1)*6+3,2)&"") -> INV · Próximos a vencer (3–6 meses): semáforo y propuesta de redistribución | G15: =IF(Configuración!$C$13=0,"",INDEX('Plan semanal'!$C$1:$G$40,4+(Configuración!$D$13-1)*6+3,3)&"") -> CAL · Revisión de desviaciones, reclamos, devoluciones y estado de CAPAs | I15: =IF(Configuración!$C$13=0,"",INDEX('Plan semanal'!$C$1:$G$40,4+(Configuración!$D$13-1)*6+3,4)&"") -> REG · Farmacovigilancia y tecnovigilancia: revisar y notificar RAM / fallas de calidad al ISP | K15: =IF(Configuración!$C$13=0,"",INDEX('Plan semanal'!$C$1:$G$40,4+(Configuración!$D$13-1)*6+3,5)&"") -> CAL · Actualizar procedimientos
B16: PM | C16: =IF(Configuración!$C$13=0,"",INDEX('Plan semanal'!$C$1:$G$40,4+(Configuración!$D$13-1)*6+4,1)&"") -> CTR · Archivo de documentación de controlados e informes a la autoridad sanitaria (según periodicidad vigente) | E16: =IF(Configuración!$C$13=0,"",INDEX('Plan semanal'!$C$1:$G$40,4+(Configuración!$D$13-1)*6+4,2)&"") -> REC · Hacer PE + ET + AG/CM/SE | G16: =IF(Configuración!$C$13=0,"",INDEX('Plan semanal'!$C$1:$G$40,4+(Configuración!$D$13-1)*6+4,3)&"") -> ADM · Facturas firmadas listas para Finanzas | I16: =IF(Configuración!$C$13=0,"",INDEX('Plan semanal'!$C$1:$G$40,4+(Configuración!$D$13-1)*6+4,4)&"") -> REC · Críticos + PE / Programación 2 QF | K16: =IF(Configuración!$C$13=0,"",INDEX('Plan semanal'!$C$1:$G$40,4+(Configuración!$D$13-1)*6+4,5)&"") -> EQP · Capacitación mensual al personal (BPAD, control de T° y HR, derrames, controlados) + registro de asistencia
A18: ="SEMANA 3" -> SEMANA 3 | B18: =IF(Configuración!$C$14=0,"No aplica este mes","Plan Semana "&Configuración!$D$14&" · "&INDEX('Plan semanal'!$B$1:$B$40,4+(Configuración!$D$14-1)*6)) -> Plan Semana 3 · CALIDAD, INVENTARIO Y PLANIFICACIÓN DE RECEPCIÓN | M18: Avance
B19: Fecha | C19: =Configuración!$B$14+0 -> 46342 | D19: =C19 -> 46342 | E19: =Configuración!$B$14+1 -> 46343 | F19: =E19 -> 46343 | G19: =Configuración!$B$14+2 -> 46344 | H19: =G19 -> 46344 | I19: =Configuración!$B$14+3 -> 46345 | J19: =I19 -> 46345 | K19: =Configuración!$B$14+4 -> 46346 | L19: =K19 -> 46346 | M19: =IFERROR(((COUNTIF(Configuración!$M$4:$M$80,C$19)=0)*(D21="✓")+(COUNTIF(Configuración!$M$4:$M$80,C$19)=0)*(D22="✓")+(COUNTIF(Configuración!$M$4:$M$80,E$19)=0)*(F21="✓")+(COUNTIF(Configuración!$M$4:$M$80,E$19)=0)*(F22="✓")+(COUNTIF(Configuración!$M$4:$M$80,G$19)=0)*(H21="✓")+(COUNTIF(Configuración!$M$4:$M$80,G$19)=0)*(H22="✓")+(COUNTIF(Configuración!$M$4:$M$80,I$19)=0)*(J21="✓")+(COUNTIF(Configuración!$M$4:$M$80,I$19)=0)*(J22="✓")+(COUNTIF(Configuración!$M$4:$M$80,K$19)=0)*(L21="✓")+(COUNTIF(Configuración!$M$4:$M$80,K$19)=0)*(L22="✓"))/((COUNTIF(Configuración!$M$4:$M$80,C$19)=0)*(C21<>"")*(D21<>"N/A")+(COUNTIF(Configuración!$M$4:$M$80,C$19)=0)*(C22<>"")*(D22<>"N/A")+(COUNTIF(Configuración!$M$4:$M$80,E$19)=0)*(E21<>"")*(F21<>"N/A")+(COUNTIF(Configuración!$M$4:$M$80,E$19)=0)*(E22<>"")*(F22<>"N/A")+(COUNTIF(Configuración!$M$4:$M$80,G$19)=0)*(G21<>"")*(H21<>"N/A")+(COUNTIF(Configuración!$M$4:$M$80,G$19)=0)*(G22<>"")*(H22<>"N/A")+(COUNTIF(Configuración!$M$4:$M$80,I$19)=0)*(I21<>"")*(J21<>"N/A")+(COUNTIF(Configuración!$M$4:$M$80,I$19)=0)*(I22<>"")*(J22<>"N/A")+(COUNTIF(Configuración!$M$4:$M$80,K$19)=0)*(K21<>"")*(L21<>"N/A")+(COUNTIF(Configuración!$M$4:$M$80,K$19)=0)*(K22<>"")*(L22<>"N/A")),"") -> 0
B20: Todos los días | C20: =IF(Configuración!$C$14=0,"",INDEX('Plan semanal'!$C$1:$C$40,4+(Configuración!$D$14-1)*6+2)&"") -> T° y HR AM/PM en bodegas · Revisión y firma de despachos · Revisión de alertas ISP / retiros del mercado · Custodia de bodega de controlados
B21: AM | C21: =IF(Configuración!$C$14=0,"",INDEX('Plan semanal'!$C$1:$G$40,4+(Configuración!$D$14-1)*6+3,1)&"") -> INV · Inventario cíclico (alta rotación / alto costo) y ajustes en sistema | E21: =IF(Configuración!$C$14=0,"",INDEX('Plan semanal'!$C$1:$G$40,4+(Configuración!$D$14-1)*6+3,2)&"") -> INV · Correo sobrestock (HPM-SSDR-SAR-SAPU) | G21: =IF(Configuración!$C$14=0,"",INDEX('Plan semanal'!$C$1:$G$40,4+(Configuración!$D$14-1)*6+3,3)&"") -> CAL · Verificar registros de limpieza y control de plagas (certificados vigentes) | I21: =IF(Configuración!$C$14=0,"",INDEX('Plan semanal'!$C$1:$G$40,4+(Configuración!$D$14-1)*6+3,4)&"") -> TEM · Equipos: calibración de data loggers/termómetros, mantención de equipos de AC, prueba de alarmas | K21: =IF(Configuración!$C$14=0,"",INDEX('Plan semanal'!$C$1:$G$40,4+(Configuración!$D$14-1)*6+3,5)&"") -> CAL · Actualizar procedimientos
B22: PM | C22: =IF(Configuración!$C$14=0,"",INDEX('Plan semanal'!$C$1:$G$40,4+(Configuración!$D$14-1)*6+4,1)&"") -> CAL · Autoinspección BPAD por área (rotativa): orden, rotulación, segregación, FEFO | E22: =IF(Configuración!$C$14=0,"",INDEX('Plan semanal'!$C$1:$G$40,4+(Configuración!$D$14-1)*6+4,2)&"") -> EQP · 16:00 a 17:00 reunión Equipo Droguería | G22: =IF(Configuración!$C$14=0,"",INDEX('Plan semanal'!$C$1:$G$40,4+(Configuración!$D$14-1)*6+4,3)&"") -> ADM · Facturas firmadas listas para Finanzas | I22: =IF(Configuración!$C$14=0,"",INDEX('Plan semanal'!$C$1:$G$40,4+(Configuración!$D$14-1)*6+4,4)&"") -> REC · Planificar recepciones semanas 4 y 1: espacio, personal, control de T°/HR y agenda CENABAST | K22: =IF(Configuración!$C$14=0,"",INDEX('Plan semanal'!$C$1:$G$40,4+(Configuración!$D$14-1)*6+4,5)&"") -> ADM · Indicadores del mes: quiebres de stock, mermas, excursiones de T°, cumplimiento de despachos
A24: ="SEMANA 4" -> SEMANA 4 | B24: =IF(Configuración!$C$15=0,"No aplica este mes","Plan Semana "&Configuración!$D$15&" · "&INDEX('Plan semanal'!$B$1:$B$40,4+(Configuración!$D$15-1)*6)) -> Plan Semana 4 · RECEPCIÓN DE CENABAST | M24: Avance
B25: Fecha | C25: =Configuración!$B$15+0 -> 46349 | D25: =C25 -> 46349 | E25: =Configuración!$B$15+1 -> 46350 | F25: =E25 -> 46350 | G25: =Configuración!$B$15+2 -> 46351 | H25: =G25 -> 46351 | I25: =Configuración!$B$15+3 -> 46352 | J25: =I25 -> 46352 | K25: =Configuración!$B$15+4 -> 46353 | L25: =K25 -> 46353 | M25: =IFERROR(((COUNTIF(Configuración!$M$4:$M$80,C$25)=0)*(D27="✓")+(COUNTIF(Configuración!$M$4:$M$80,C$25)=0)*(D28="✓")+(COUNTIF(Configuración!$M$4:$M$80,E$25)=0)*(F27="✓")+(COUNTIF(Configuración!$M$4:$M$80,E$25)=0)*(F28="✓")+(COUNTIF(Configuración!$M$4:$M$80,G$25)=0)*(H27="✓")+(COUNTIF(Configuración!$M$4:$M$80,G$25)=0)*(H28="✓")+(COUNTIF(Configuración!$M$4:$M$80,I$25)=0)*(J27="✓")+(COUNTIF(Configuración!$M$4:$M$80,I$25)=0)*(J28="✓")+(COUNTIF(Configuración!$M$4:$M$80,K$25)=0)*(L27="✓")+(COUNTIF(Configuración!$M$4:$M$80,K$25)=0)*(L28="✓"))/((COUNTIF(Configuración!$M$4:$M$80,C$25)=0)*(C27<>"")*(D27<>"N/A")+(COUNTIF(Configuración!$M$4:$M$80,C$25)=0)*(C28<>"")*(D28<>"N/A")+(COUNTIF(Configuración!$M$4:$M$80,E$25)=0)*(E27<>"")*(F27<>"N/A")+(COUNTIF(Configuración!$M$4:$M$80,E$25)=0)*(E28<>"")*(F28<>"N/A")+(COUNTIF(Configuración!$M$4:$M$80,G$25)=0)*(G27<>"")*(H27<>"N/A")+(COUNTIF(Configuración!$M$4:$M$80,G$25)=0)*(G28<>"")*(H28<>"N/A")+(COUNTIF(Configuración!$M$4:$M$80,I$25)=0)*(I27<>"")*(J27<>"N/A")+(COUNTIF(Configuración!$M$4:$M$80,I$25)=0)*(I28<>"")*(J28<>"N/A")+(COUNTIF(Configuración!$M$4:$M$80,K$25)=0)*(K27<>"")*(L27<>"N/A")+(COUNTIF(Configuración!$M$4:$M$80,K$25)=0)*(K28<>"")*(L28<>"N/A")),"") -> 0
B26: Todos los días | C26: =IF(Configuración!$C$15=0,"",INDEX('Plan semanal'!$C$1:$C$40,4+(Configuración!$D$15-1)*6+2)&"") -> T° y HR AM/PM en bodegas · Recepción técnica y liberación de cuarentena · Revisión de alertas ISP / retiros del mercado
B27: AM | C27: =IF(Configuración!$C$15=0,"",INDEX('Plan semanal'!$C$1:$G$40,4+(Configuración!$D$15-1)*6+3,1)&"") -> REC · Recepción CENABAST: inspección de lotes, vencimientos, T° de transporte y documentación | E27: =IF(Configuración!$C$15=0,"",INDEX('Plan semanal'!$C$1:$G$40,4+(Configuración!$D$15-1)*6+3,2)&"") -> REC · Críticos + PE | G27: =IF(Configuración!$C$15=0,"",INDEX('Plan semanal'!$C$1:$G$40,4+(Configuración!$D$15-1)*6+3,3)&"") | I27: =IF(Configuración!$C$15=0,"",INDEX('Plan semanal'!$C$1:$G$40,4+(Configuración!$D$15-1)*6+3,4)&"") -> REC · Críticos + PE | K27: =IF(Configuración!$C$15=0,"",INDEX('Plan semanal'!$C$1:$G$40,4+(Configuración!$D$15-1)*6+3,5)&"") -> CAL · Liberar cuarentena pendiente y verificar ubicación/rotulación (FEFO)
B28: PM | C28: =IF(Configuración!$C$15=0,"",INDEX('Plan semanal'!$C$1:$G$40,4+(Configuración!$D$15-1)*6+4,1)&"") -> TEM · Vigilar T° y HR de bodegas durante la recepción (puertas abiertas, sobreocupación) y aplicar CAPA si hay excursión | E28: =IF(Configuración!$C$15=0,"",INDEX('Plan semanal'!$C$1:$G$40,4+(Configuración!$D$15-1)*6+4,2)&"") -> REC · No conformidades de recepción (faltantes, daños, T° fuera de rango) → reclamo a CENABAST/proveedor | G28: =IF(Configuración!$C$15=0,"",INDEX('Plan semanal'!$C$1:$G$40,4+(Configuración!$D$15-1)*6+4,3)&"") -> ADM · Facturas firmadas listas para Finanzas | I28: =IF(Configuración!$C$15=0,"",INDEX('Plan semanal'!$C$1:$G$40,4+(Configuración!$D$15-1)*6+4,4)&"") | K28: =IF(Configuración!$C$15=0,"",INDEX('Plan semanal'!$C$1:$G$40,4+(Configuración!$D$15-1)*6+4,5)&"") -> ADM · Cierre de mes: guías, documentos de despacho y stock cuadrados
A30: ="SEMANA 5" -> SEMANA 5 | B30: =IF(Configuración!$C$16=0,"No aplica este mes","Plan Semana "&Configuración!$D$16&" · "&INDEX('Plan semanal'!$B$1:$B$40,4+(Configuración!$D$16-1)*6)) -> No aplica este mes | M30: Avance
B31: Fecha | C31: =Configuración!$B$16+0 -> 46356 | D31: =C31 -> 46356 | E31: =Configuración!$B$16+1 -> 46357 | F31: =E31 -> 46357 | G31: =Configuración!$B$16+2 -> 46358 | H31: =G31 -> 46358 | I31: =Configuración!$B$16+3 -> 46359 | J31: =I31 -> 46359 | K31: =Configuración!$B$16+4 -> 46360 | L31: =K31 -> 46360 | M31: =IFERROR(((COUNTIF(Configuración!$M$4:$M$80,C$31)=0)*(D33="✓")+(COUNTIF(Configuración!$M$4:$M$80,C$31)=0)*(D34="✓")+(COUNTIF(Configuración!$M$4:$M$80,E$31)=0)*(F33="✓")+(COUNTIF(Configuración!$M$4:$M$80,E$31)=0)*(F34="✓")+(COUNTIF(Configuración!$M$4:$M$80,G$31)=0)*(H33="✓")+(COUNTIF(Configuración!$M$4:$M$80,G$31)=0)*(H34="✓")+(COUNTIF(Configuración!$M$4:$M$80,I$31)=0)*(J33="✓")+(COUNTIF(Configuración!$M$4:$M$80,I$31)=0)*(J34="✓")+(COUNTIF(Configuración!$M$4:$M$80,K$31)=0)*(L33="✓")+(COUNTIF(Configuración!$M$4:$M$80,K$31)=0)*(L34="✓"))/((COUNTIF(Configuración!$M$4:$M$80,C$31)=0)*(C33<>"")*(D33<>"N/A")+(COUNTIF(Configuración!$M$4:$M$80,C$31)=0)*(C34<>"")*(D34<>"N/A")+(COUNTIF(Configuración!$M$4:$M$80,E$31)=0)*(E33<>"")*(F33<>"N/A")+(COUNTIF(Configuración!$M$4:$M$80,E$31)=0)*(E34<>"")*(F34<>"N/A")+(COUNTIF(Configuración!$M$4:$M$80,G$31)=0)*(G33<>"")*(H33<>"N/A")+(COUNTIF(Configuración!$M$4:$M$80,G$31)=0)*(G34<>"")*(H34<>"N/A")+(COUNTIF(Configuración!$M$4:$M$80,I$31)=0)*(I33<>"")*(J33<>"N/A")+(COUNTIF(Configuración!$M$4:$M$80,I$31)=0)*(I34<>"")*(J34<>"N/A")+(COUNTIF(Configuración!$M$4:$M$80,K$31)=0)*(K33<>"")*(L33<>"N/A")+(COUNTIF(Configuración!$M$4:$M$80,K$31)=0)*(K34<>"")*(L34<>"N/A")),"")
B32: Todos los días | C32: =IF(Configuración!$C$16=0,"",INDEX('Plan semanal'!$C$1:$C$40,4+(Configuración!$D$16-1)*6+2)&"")
B33: AM | C33: =IF(Configuración!$C$16=0,"",INDEX('Plan semanal'!$C$1:$G$40,4+(Configuración!$D$16-1)*6+3,1)&"") | E33: =IF(Configuración!$C$16=0,"",INDEX('Plan semanal'!$C$1:$G$40,4+(Configuración!$D$16-1)*6+3,2)&"") | G33: =IF(Configuración!$C$16=0,"",INDEX('Plan semanal'!$C$1:$G$40,4+(Configuración!$D$16-1)*6+3,3)&"") | I33: =IF(Configuración!$C$16=0,"",INDEX('Plan semanal'!$C$1:$G$40,4+(Configuración!$D$16-1)*6+3,4)&"") | K33: =IF(Configuración!$C$16=0,"",INDEX('Plan semanal'!$C$1:$G$40,4+(Configuración!$D$16-1)*6+3,5)&"")
B34: PM | C34: =IF(Configuración!$C$16=0,"",INDEX('Plan semanal'!$C$1:$G$40,4+(Configuración!$D$16-1)*6+4,1)&"") | E34: =IF(Configuración!$C$16=0,"",INDEX('Plan semanal'!$C$1:$G$40,4+(Configuración!$D$16-1)*6+4,2)&"") | G34: =IF(Configuración!$C$16=0,"",INDEX('Plan semanal'!$C$1:$G$40,4+(Configuración!$D$16-1)*6+4,3)&"") | I34: =IF(Configuración!$C$16=0,"",INDEX('Plan semanal'!$C$1:$G$40,4+(Configuración!$D$16-1)*6+4,4)&"") | K34: =IF(Configuración!$C$16=0,"",INDEX('Plan semanal'!$C$1:$G$40,4+(Configuración!$D$16-1)*6+4,5)&"")
A36: Periódicas del mes | C36: =IF(_xlfn.TEXTJOIN(" · ",TRUE(),Periódicas!$Q$5:$Q$22)="","Sin tareas periódicas este mes",_xlfn.TEXTJOIN(" · ",TRUE(),Periódicas!$Q$5:$Q$22)) -> Simulacro plan de contingencia de T°/HR (corte de energía / falla de AC)

Sheet Plan semanal
A1: PLAN SEMANAL TIPO – QUÍMICO FARMACÉUTICO DROGUERÍA
A2: Edita aquí las tareas; el Calendario las toma automáticamente. Escribe cada tarea como CÓDIGO · tarea (ej.: CTR · Revisión de libro). El código de 3 letras le da el color. Semanas 1 y 4 = alta recepción: se dejan espacios libres.
A4: SEMANA 1 | B4: RECEPCIÓN CENABAST / CRÍTICOS Y PE LISTOS
C5: Lunes | D5: Martes | E5: Miércoles | F5: Jueves | G5: Viernes
B6: Todos los días | C6: T° y HR AM/PM en bodegas · Recepción técnica y liberación de cuarentena · Revisión de alertas ISP / retiros del mercado
B7: AM | C7: TEM · Bajar info Data Logger / Revisión QFs: T° y H% aplicar CAPAs | D7: INV · Segregar vencidos + correo sobrestock (HPM-SSDR-SAR-SAPU) | E7: REC · Críticos + PE | F7: EQP · QF Programas / QF Droguería | G7: ADM · Guía N399
B8: PM | C8: CTR · Cuadratura física de estupefacientes y psicotrópicos (cierre mes anterior) | D8: REC · No conformidades de recepción (faltantes, daños, T° fuera de rango) → reclamo a CENABAST/proveedor | E8: ADM · Facturas firmadas listas para Finanzas | F8: EQP · Programación 2 QF | G8: CAL · Actualizar procedimientos
A10: SEMANA 2 | B10: GESTIÓN SANITARIA: CONTROLADOS, VENCIMIENTOS Y FARMACOVIGILANCIA
C11: Lunes | D11: Martes | E11: Miércoles | F11: Jueves | G11: Viernes
B12: Todos los días | C12: T° y HR AM/PM en bodegas · Revisión y firma de despachos · Revisión de alertas ISP / retiros del mercado · Custodia de bodega de controlados
B13: AM | C13: CTR · Revisión de libro de controlados | D13: INV · Próximos a vencer (3–6 meses): semáforo y propuesta de redistribución | E13: CAL · Revisión de desviaciones, reclamos, devoluciones y estado de CAPAs | F13: REG · Farmacovigilancia y tecnovigilancia: revisar y notificar RAM / fallas de calidad al ISP | G13: CAL · Actualizar procedimientos
B14: PM | C14: CTR · Archivo de documentación de controlados e informes a la autoridad sanitaria (según periodicidad vigente) | D14: REC · Hacer PE + ET + AG/CM/SE | E14: ADM · Facturas firmadas listas para Finanzas | F14: REC · Críticos + PE / Programación 2 QF | G14: EQP · Capacitación mensual al personal (BPAD, control de T° y HR, derrames, controlados) + registro de asistencia
A16: SEMANA 3 | B16: CALIDAD, INVENTARIO Y PLANIFICACIÓN DE RECEPCIÓN
C17: Lunes | D17: Martes | E17: Miércoles | F17: Jueves | G17: Viernes
B18: Todos los días | C18: T° y HR AM/PM en bodegas · Revisión y firma de despachos · Revisión de alertas ISP / retiros del mercado · Custodia de bodega de controlados
B19: AM | C19: INV · Inventario cíclico (alta rotación / alto costo) y ajustes en sistema | D19: INV · Correo sobrestock (HPM-SSDR-SAR-SAPU) | E19: CAL · Verificar registros de limpieza y control de plagas (certificados vigentes) | F19: TEM · Equipos: calibración de data loggers/termómetros, mantención de equipos de AC, prueba de alarmas | G19: CAL · Actualizar procedimientos
B20: PM | C20: CAL · Autoinspección BPAD por área (rotativa): orden, rotulación, segregación, FEFO | D20: EQP · 16:00 a 17:00 reunión Equipo Droguería | E20: ADM · Facturas firmadas listas para Finanzas | F20: REC · Planificar recepciones semanas 4 y 1: espacio, personal, control de T°/HR y agenda CENABAST | G20: ADM · Indicadores del mes: quiebres de stock, mermas, excursiones de T°, cumplimiento de despachos
A22: SEMANA 4 | B22: RECEPCIÓN DE CENABAST
C23: Lunes | D23: Martes | E23: Miércoles | F23: Jueves | G23: Viernes
B24: Todos los días | C24: T° y HR AM/PM en bodegas · Recepción técnica y liberación de cuarentena · Revisión de alertas ISP / retiros del mercado
B25: AM | C25: REC · Recepción CENABAST: inspección de lotes, vencimientos, T° de transporte y documentación | D25: REC · Críticos + PE | F25: REC · Críticos + PE | G25: CAL · Liberar cuarentena pendiente y verificar ubicación/rotulación (FEFO)
B26: PM | C26: TEM · Vigilar T° y HR de bodegas durante la recepción (puertas abiertas, sobreocupación) y aplicar CAPA si hay excursión | D26: REC · No conformidades de recepción (faltantes, daños, T° fuera de rango) → reclamo a CENABAST/proveedor | E26: ADM · Facturas firmadas listas para Finanzas | G26: ADM · Cierre de mes: guías, documentos de despacho y stock cuadrados

Sheet Periódicas
A1: TAREAS PERIÓDICAS (TRIMESTRALES, SEMESTRALES Y ANUALES)
A2: Marca con X el mes en que corresponde. Meses sugeridos: ajústalos. El mes elegido en el Calendario se resalta.
A4: Código | B4: Tarea | C4: Frecuencia | D4: Ene | E4: Feb | F4: Mar | G4: Abr | H4: May | I4: Jun | J4: Jul | K4: Ago | L4: Sep | M4: Oct | N4: Nov | O4: Dic
A5: TEM | B5: Mapeo térmico Bodega 4 (verano / invierno) | C5: Semestral | E5: X | J5: X | Q5: =IF(INDEX($D5:$O5,Configuración!$B$4)="X",B5,"")
A6: TEM | B6: Calibración / verificación de data loggers y termómetros | C6: Anual | F6: X | Q6: =IF(INDEX($D6:$O6,Configuración!$B$4)="X",B6,"")
A7: TEM | B7: Mantención preventiva de equipos de AC de bodegas | C7: Semestral | G7: X | M7: X | Q7: =IF(INDEX($D7:$O7,Configuración!$B$4)="X",B7,"")
A8: TEM | B8: Simulacro plan de contingencia de T°/HR (corte de energía / falla de AC) | C8: Semestral | H8: X | N8: X | Q8: =IF(INDEX($D8:$O8,Configuración!$B$4)="X",B8,"") -> Simulacro plan de contingencia de T°/HR (corte de energía / falla de AC)
A9: INV | B9: Eliminación de vencidos y mermas mediante empresa autorizada | C9: Semestral | D9: X | J9: X | Q9: =IF(INDEX($D9:$O9,Configuración!$B$4)="X",B9,"")
A10: CTR | B10: Destrucción de controlados vencidos/deteriorados (solicitud y acta ante autoridad sanitaria) | C10: Semestral | G10: X | M10: X | Q10: =IF(INDEX($D10:$O10,Configuración!$B$4)="X",B10,"")
A11: INV | B11: Inventario general (toma total de inventario) | C11: Semestral | I11: X | O11: X | Q11: =IF(INDEX($D11:$O11,Configuración!$B$4)="X",B11,"")
A12: CAL | B12: Autoinspección integral BPAD (todas las áreas) + informe | C12: Anual | I12: X | Q12: =IF(INDEX($D12:$O12,Configuración!$B$4)="X",B12,"")
A13: CAL | B13: Evaluación de proveedores y transportistas | C13: Anual | K13: X | Q13: =IF(INDEX($D13:$O13,Configuración!$B$4)="X",B13,"")
A14: CAL | B14: Revisión del listado maestro de procedimientos (vigencias y versiones) | C14: Anual | O14: X | Q14: =IF(INDEX($D14:$O14,Configuración!$B$4)="X",B14,"")
A15: EQP | B15: Programa anual de capacitación: planificar (ene) / evaluar cumplimiento (dic) | C15: Anual | D15: X | J15: X | O15: X | Q15: =IF(INDEX($D15:$O15,Configuración!$B$4)="X",B15,"")
A16: ADM | B16: Carpeta documental: autorización sanitaria, dirección técnica, certificados vigentes | C16: Anual | D16: X | Q16: =IF(INDEX($D16:$O16,Configuración!$B$4)="X",B16,"")
Q17: =IF(INDEX($D17:$O17,Configuración!$B$4)="X",B17,"")
Q18: =IF(INDEX($D18:$O18,Configuración!$B$4)="X",B18,"")
Q19: =IF(INDEX($D19:$O19,Configuración!$B$4)="X",B19,"")
Q20: =IF(INDEX($D20:$O20,Configuración!$B$4)="X",B20,"")
Q21: =IF(INDEX($D21:$O21,Configuración!$B$4)="X",B21,"")
Q22: =IF(INDEX($D22:$O22,Configuración!$B$4)="X",B22,"")

Sheet Detalle de tareas
A1: DETALLE DE TAREAS, EVIDENCIA Y RESPALDO NORMATIVO
A2: Referencia del plan tipo (la hoja Plan semanal es la que manda). Origen = Original (ya estaba en tu planilla) o Nueva (agregada). Referencias normativas sugeridas: verificar vigencia.
A4: Semana | B4: Día | C4: Bloque | D4: Código | E4: Tipo de tarea | F4: Tarea | G4: Origen | H4: Registro / evidencia | I4: Referencia sugerida
A5: Todas | B5: Lun a Vie | C5: Diario | D5: TEM | E5: Temperatura y humedad (T° y HR) | F5: Registro de T° y HR AM/PM en bodegas; revisión de alarmas | G5: Nueva | H5: Planilla de T° / data logger | I5: NT 147 BPAD
A6: 1 y 4 | B6: Lun a Vie | C6: Diario | D6: REC | E6: Recepción, pedidos y distribución | F6: Recepción técnica y liberación de cuarentena por QF | G6: Nueva | H6: Acta de recepción / liberación | I6: NT 147 BPAD
A7: 2 y 3 | B7: Lun a Vie | C7: Diario | D7: REC | E7: Recepción, pedidos y distribución | F7: Revisión y firma de despachos | G7: Nueva | H7: Guías firmadas | I7: NT 147 BPAD
A8: Todas | B8: Lun a Vie | C8: Diario | D8: REG | E8: Farmacovigilancia y autoridad sanitaria | F8: Revisión de alertas ISP / retiros del mercado (y acción inmediata si afecta stock) | G8: Nueva | H8: Registro de alertas revisadas | I8: DS 3/2010
A9: 2 y 3 | B9: Lun a Vie | C9: Diario | D9: CTR | E9: Estupefacientes y psicotrópicos | F9: Custodia de bodega de controlados (llaves, acceso restringido) | G9: Nueva | I9: DS 404 / DS 405
A10: 1 | B10: Lunes | C10: AM | D10: TEM | E10: Temperatura y humedad (T° y HR) | F10: Bajar info Data Logger / Revisión QFs: T° y H% aplicar CAPAs | G10: Original | H10: Informe data logger + CAPA | I10: NT 147 BPAD
A11: 1 | B11: Lunes | C11: PM | D11: CTR | E11: Estupefacientes y psicotrópicos | F11: Cuadratura física de estupefacientes y psicotrópicos (cierre mes anterior) | G11: Nueva | H11: Acta de cuadratura firmada | I11: DS 404 / DS 405
A12: 1 | B12: Martes | C12: AM | D12: INV | E12: Inventario y vencimientos | F12: Segregar vencidos + correo sobrestock (HPM-SSDR-SAR-SAPU) | G12: Original | H12: Registro de segregación / correo | I12: NT 147 BPAD
A13: 1 | B13: Martes | C13: PM | D13: REC | E13: Recepción, pedidos y distribución | F13: No conformidades de recepción (faltantes, daños, T° fuera de rango) → reclamo a CENABAST/proveedor | G13: Nueva | H13: Registro de no conformidad / correo de reclamo | I13: NT 147 BPAD (recepción)
A14: 1 | B14: Miércoles | C14: AM | D14: REC | E14: Recepción, pedidos y distribución | F14: Críticos + PE | G14: Original | H14: Pedido de críticos y PE
A15: 1 | B15: Miércoles | C15: PM | D15: ADM | E15: Administrativo y finanzas | F15: Facturas firmadas listas para Finanzas | G15: Original | H15: Facturas firmadas / registro de entrega
A16: 1 | B16: Jueves | C16: AM | D16: EQP | E16: Equipo, coordinación y capacitación | F16: QF Programas / QF Droguería | G16: Original
A17: 1 | B17: Jueves | C17: PM | D17: EQP | E17: Equipo, coordinación y capacitación | F17: Programación 2 QF | G17: Original
A18: 1 | B18: Viernes | C18: AM | D18: ADM | E18: Administrativo y finanzas | F18: Guía N399 | G18: Original
A19: 1 | B19: Viernes | C19: PM | D19: CAL | E19: Calidad / BPAD / procedimientos | F19: Actualizar procedimientos | G19: Original | H19: Procedimientos DRORED versionados | I19: NT 147 BPAD
A20: 2 | B20: Lunes | C20: AM | D20: CTR | E20: Estupefacientes y psicotrópicos | F20: Revisión de libro de controlados | G20: Original | H20: Libro oficial visado | I20: DS 404 / DS 405
A21: 2 | B21: Lunes | C21: PM | D21: CTR | E21: Estupefacientes y psicotrópicos | F21: Archivo de documentación de controlados e informes a la autoridad sanitaria (según periodicidad vigente) | G21: Nueva | H21: Informe enviado / archivo | I21: DS 404 / DS 405
A22: 2 | B22: Martes | C22: AM | D22: INV | E22: Inventario y vencimientos | F22: Próximos a vencer (3–6 meses): semáforo y propuesta de redistribución | G22: Nueva | H22: Listado de próximos a vencer | I22: NT 147 BPAD (FEFO)
A23: 2 | B23: Martes | C23: PM | D23: REC | E23: Recepción, pedidos y distribución | F23: Hacer PE + ET + AG/CM/SE | G23: Original
A24: 2 | B24: Miércoles | C24: AM | D24: CAL | E24: Calidad / BPAD / procedimientos | F24: Revisión de desviaciones, reclamos, devoluciones y estado de CAPAs | G24: Nueva | H24: Registro de desviaciones / CAPA | I24: NT 147 BPAD
A25: 2 | B25: Miércoles | C25: PM | D25: ADM | E25: Administrativo y finanzas | F25: Facturas firmadas listas para Finanzas | G25: Original | H25: Facturas firmadas / registro de entrega
A26: 2 | B26: Jueves | C26: AM | D26: REG | E26: Farmacovigilancia y autoridad sanitaria | F26: Farmacovigilancia y tecnovigilancia: revisar y notificar RAM / fallas de calidad al ISP | G26: Nueva | H26: Notificaciones ISP / registro interno | I26: DS 3/2010 · NT 140
A27: 2 | B27: Jueves | C27: PM | D27: REC | E27: Recepción, pedidos y distribución | F27: Críticos + PE / Programación 2 QF | G27: Original
A28: 2 | B28: Viernes | C28: AM | D28: CAL | E28: Calidad / BPAD / procedimientos | F28: Actualizar procedimientos | G28: Original | H28: Procedimientos DRORED versionados | I28: NT 147 BPAD
A29: 2 | B29: Viernes | C29: PM | D29: EQP | E29: Equipo, coordinación y capacitación | F29: Capacitación mensual al personal (BPAD, control de T° y HR, derrames, controlados) + registro de asistencia | G29: Nueva | H29: Registro de asistencia | I29: NT 147 BPAD (personal)
A30: 3 | B30: Lunes | C30: AM | D30: INV | E30: Inventario y vencimientos | F30: Inventario cíclico (alta rotación / alto costo) y ajustes en sistema | G30: Nueva | H30: Acta de inventario / ajustes | I30: NT 147 BPAD
A31: 3 | B31: Lunes | C31: PM | D31: CAL | E31: Calidad / BPAD / procedimientos | F31: Autoinspección BPAD por área (rotativa): orden, rotulación, segregación, FEFO | G31: Nueva | H31: Pauta de autoinspección | I31: NT 147 BPAD (autoinspección)
A32: 3 | B32: Martes | C32: AM | D32: INV | E32: Inventario y vencimientos | F32: Correo sobrestock (HPM-SSDR-SAR-SAPU) | G32: Original | H32: Correo enviado
A33: 3 | B33: Martes | C33: PM | D33: EQP | E33: Equipo, coordinación y capacitación | F33: 16:00 a 17:00 reunión Equipo Droguería | G33: Original | H33: Acta de reunión
A34: 3 | B34: Miércoles | C34: AM | D34: CAL | E34: Calidad / BPAD / procedimientos | F34: Verificar registros de limpieza y control de plagas (certificados vigentes) | G34: Nueva | H34: Planilla de limpieza / certificado | I34: NT 147 BPAD
A35: 3 | B35: Miércoles | C35: PM | D35: ADM | E35: Administrativo y finanzas | F35: Facturas firmadas listas para Finanzas | G35: Original | H35: Facturas firmadas / registro de entrega
A36: 3 | B36: Jueves | C36: AM | D36: TEM | E36: Temperatura y humedad (T° y HR) | F36: Equipos: calibración de data loggers/termómetros, mantención de equipos de AC, prueba de alarmas | G36: Nueva | H36: Certificados / registro de mantención | I36: NT 147 BPAD
A37: 3 | B37: Jueves | C37: PM | D37: REC | E37: Recepción, pedidos y distribución | F37: Planificar recepciones semanas 4 y 1: espacio, personal, control de T°/HR y agenda CENABAST | G37: Nueva | H37: Plan de recepción
A38: 3 | B38: Viernes | C38: AM | D38: CAL | E38: Calidad / BPAD / procedimientos | F38: Actualizar procedimientos | G38: Original | H38: Procedimientos DRORED versionados | I38: NT 147 BPAD
A39: 3 | B39: Viernes | C39: PM | D39: ADM | E39: Administrativo y finanzas | F39: Indicadores del mes: quiebres de stock, mermas, excursiones de T°, cumplimiento de despachos | G39: Nueva | H39: Reporte de indicadores
A40: 4 | B40: Lunes | C40: AM | D40: REC | E40: Recepción, pedidos y distribución | F40: Recepción CENABAST: inspección de lotes, vencimientos, T° de transporte y documentación | G40: Nueva | H40: Acta de recepción técnica | I40: NT 147 BPAD (recepción)
A41: 4 | B41: Lunes | C41: PM | D41: TEM | E41: Temperatura y humedad (T° y HR) | F41: Vigilar T° y HR de bodegas durante la recepción (puertas abiertas, sobreocupación) y aplicar CAPA si hay excursión | G41: Nueva | H41: Registro de T° | I41: NT 147 BPAD
...

Sheet Configuración
A1: CONFIGURACIÓN Y LISTAS
A3: Cálculos automáticos (no editar) | H3: Meses | J3: Código | K3: Tipo de tarea | M3: Feriados (fecha) | N3: Descripción
A4: Mes (número) | B4: =MATCH(Calendario!$C$2,$H$4:$H$15,0) -> 11 | H4: Enero | J4: REC | K4: Recepción, pedidos y distribución | M4: 46364 | N4: Inmaculada Concepción
A5: Primer día del mes | B5: =DATE(Calendario!$F$2,B4,1) -> 46327 | H5: Febrero | J5: TEM | K5: Temperatura y humedad (T° y HR) | M5: 46381 | N5: Navidad
A6: Día de la semana del 1° (1=lunes) | B6: =WEEKDAY(B5,2) -> 7 | H6: Marzo | J6: INV | K6: Inventario y vencimientos | M6: 46388 | N6: Año Nuevo
A7: Lunes de la semana 1 | B7: =IF(B6<=3,B5-B6+1,B5-B6+8) -> 46328 | H7: Abril | J7: CTR | K7: Estupefacientes y psicotrópicos | M7: 46472 | N7: Viernes Santo
A8: Último día del mes | B8: =EOMONTH(B5,0) -> 46356 | H8: Mayo | J8: CAL | K8: Calidad / BPAD / procedimientos | M8: 46528 | N8: Glorias Navales
A9: N° de semanas del mes | B9: =INT((B8-(B7+2))/7)+1 -> 4 | H9: Junio | J9: REG | K9: Farmacovigilancia y autoridad sanitaria | M9: 46559 | N9: Día de los Pueblos Indígenas
H10: Julio | J10: ADM | K10: Administrativo y finanzas | M10: 46566 | N10: San Pedro y San Pablo
A11: Semana | B11: Lunes | C11: Existe | D11: Plan aplicado | H11: Agosto | J11: EQP | K11: Equipo, coordinación y capacitación | M11: 46584 | N11: Virgen del Carmen
A12: 1 | B12: =$B$7+7*(A12-1) -> 46328 | C12: =IF(A12<=$B$9,1,0) -> 1 | D12: =IF(C12=0,0,IF(A12=1,1,IF(A12=$B$9,4,IF(A12<=3,A12,Calendario!$K$2)))) -> 1 | H12: Septiembre | M12: 46671 | N12: Encuentro de Dos Mundos
A13: 2 | B13: =$B$7+7*(A13-1) -> 46335 | C13: =IF(A13<=$B$9,1,0) -> 1 | D13: =IF(C13=0,0,IF(A13=1,1,IF(A13=$B$9,4,IF(A13<=3,A13,Calendario!$K$2)))) -> 2 | H13: Octubre | M13: 46692 | N13: Todos los Santos
A14: 3 | B14: =$B$7+7*(A14-1) -> 46342 | C14: =IF(A14<=$B$9,1,0) -> 1 | D14: =IF(C14=0,0,IF(A14=1,1,IF(A14=$B$9,4,IF(A14<=3,A14,Calendario!$K$2)))) -> 3 | H14: Noviembre | M14: 46729 | N14: Inmaculada Concepción
A15: 4 | B15: =$B$7+7*(A15-1) -> 46349 | C15: =IF(A15<=$B$9,1,0) -> 1 | D15: =IF(C15=0,0,IF(A15=1,1,IF(A15=$B$9,4,IF(A15<=3,A15,Calendario!$K$2)))) -> 4 | H15: Diciembre
A16: 5 | B16: =$B$7+7*(A16-1) -> 46356 | C16: =IF(A16<=$B$9,1,0) -> 0 | D16: =IF(C16=0,0,IF(A16=1,1,IF(A16=$B$9,4,IF(A16<=3,A16,Calendario!$K$2)))) -> 0
A17: Regla: 1ª semana = Plan 1 · última semana = Plan 4 · intermedias = Plan 2 y 3. En meses de 5 semanas, la 4ª usa el plan elegido en Calendario!K2.
A18: Cada semana (lun–vie) pertenece al mes que contiene su miércoles (≥3 días hábiles). Así, un lunes 30 puede quedar como Semana 1 del mes siguiente.
A20: CÓMO USAR
A21: 1. En la hoja Calendario elige Mes y Año (celdas amarillas). Las fechas, semanas y tareas se ajustan solas.
A22: 2. Marca cada tarea en su columna ✓ con ✓ (hecha), ✗ (no hecha) o N/A. El avance semanal se calcula solo. Borra las marcas al iniciar un mes nuevo.
A23: 3. Para cambiar o agregar tareas, edita la hoja Plan semanal (formato CÓDIGO · tarea). No edites el Calendario directamente: sus tareas son fórmulas.
A24: 4. Fechas en rojo = feriado (sus tareas quedan en gris y no cuentan en el avance: reprogramarlas). Fechas en cursiva = día de un mes contiguo que igual pertenece a esta planificación.
A25: 5. Las tareas trimestrales/semestrales/anuales están en la hoja Periódicas y aparecen al pie del Calendario en su mes.

Sheet Versión original
A2: 
A3: SEMANA 1 | B3: RECEPCIÓN CENABAST / CRÍTICOS Y PE LISTOS
B4: Lunes | C4: Martes | D4: Miércoles | E4: Jueves | F4: Viernes
B5: AM: Bajar Info Data Logger / Revisión QFs: T° y H% aplicar CAPAs | C5: AM: segregar vencidos + correo sobrestock (HPM-SSDR-SAR-SAPU) | D5: AM: CRITICOS + PE | E5: QF PROGRAMAS/ QF DROGUERÍA | F5: GUÍA N399
D6: PM: FACTURAS FIRMADAS LISTAS PARA FINANZAS | E6: PROGRAMACIÓN 2 QF | F6: PM: Actualizar procedimientos
A7: SEMANA 2 | B7: Lunes | C7: Martes | D7: Miércoles | E7: Jueves | F7: Viernes
B8: AM: REVISIÓN DE LIBRO CONTROLADOS | F8: AM: Actualizar procedimientos
C9: PM: Hacer PE + ET + AG/CM/SE | D9: PM: FACTURAS FIRMADAS LISTAS PARA FINANZAS | E9: CRITICOS + PE / PROGRAMACIÓN 2 QF
A10: SEMANA 3 | B10: Lunes | C10: Martes | D10: Miércoles | E10: Jueves | F10: Viernes
C11: am: correo sobrestock (HPM-SSDR-SAR-SAPU) | F11: AM: Actualizar procedimientos
C12: PM: 16:00 a 17:00 reunión Equipo Droguería | D12: PM: FACTURAS FIRMADAS LISTAS PARA FINANZAS
A13: SEMANA 4 | B13: RECEPCIÓN DE CENABAST
B14: Lunes | C14: Martes | D14: Miércoles | E14: Jueves | F14: Viernes
C15: CRITICOS + PE | D15: PM: FACTURAS FIRMADAS LISTAS PARA FINANZAS | E15: CRITICOS + PE
